Some kwargs in processor config are unused and will not have any effect: image_seq_len. 
/export/fhome/vlia08/MyVirtualEnv/lib/python3.8/site-packages/bitsandbytes/cuda_setup/main.py:167: UserWarning: Welcome to bitsandbytes. For bug reports, please run

python -m bitsandbytes


  warn(msg)
Traceback (most recent call last):
  File "/export/fhome/vlia08/MyVirtualEnv/lib/python3.8/site-packages/transformers/utils/import_utils.py", line 1778, in _get_module
    return importlib.import_module("." + module_name, self.__name__)
  File "/usr/lib/python3.8/importlib/__init__.py", line 127, in import_module
    return _bootstrap._gcd_import(name[level:], package, level)
  File "<frozen importlib._bootstrap>", line 1014, in _gcd_import
  File "<frozen importlib._bootstrap>", line 991, in _find_and_load
  File "<frozen importlib._bootstrap>", line 975, in _find_and_load_unlocked
  File "<frozen importlib._bootstrap>", line 671, in _load_unlocked
  File "<frozen importlib._bootstrap_external>", line 848, in exec_module
  File "<frozen importlib._bootstrap>", line 219, in _call_with_frames_removed
  File "/export/fhome/vlia08/MyVirtualEnv/lib/python3.8/site-packages/transformers/integrations/bitsandbytes.py", line 21, in <module>
    import bitsandbytes as bnb
  File "/export/fhome/vlia08/MyVirtualEnv/lib/python3.8/site-packages/bitsandbytes/__init__.py", line 6, in <module>
    from . import cuda_setup, utils, research
  File "/export/fhome/vlia08/MyVirtualEnv/lib/python3.8/site-packages/bitsandbytes/research/__init__.py", line 1, in <module>
    from . import nn
  File "/export/fhome/vlia08/MyVirtualEnv/lib/python3.8/site-packages/bitsandbytes/research/nn/__init__.py", line 1, in <module>
    from .modules import LinearFP8Mixed, LinearFP8Global
  File "/export/fhome/vlia08/MyVirtualEnv/lib/python3.8/site-packages/bitsandbytes/research/nn/modules.py", line 8, in <module>
    from bitsandbytes.optim import GlobalOptimManager
  File "/export/fhome/vlia08/MyVirtualEnv/lib/python3.8/site-packages/bitsandbytes/optim/__init__.py", line 6, in <module>
    from bitsandbytes.cextension import COMPILED_WITH_CUDA
  File "/export/fhome/vlia08/MyVirtualEnv/lib/python3.8/site-packages/bitsandbytes/cextension.py", line 20, in <module>
    raise RuntimeError('''
RuntimeError: 
        CUDA Setup failed despite GPU being available. Please run the following command to get more information:

        python -m bitsandbytes

        Inspect the output of the command and see if you can locate CUDA libraries. You might need to add them
        to your LD_LIBRARY_PATH. If you suspect a bug, please take the information from python -m bitsandbytes
        and open an issue at: https://github.com/TimDettmers/bitsandbytes/issues

The above exception was the direct cause of the following exception:

Traceback (most recent call last):
  File "/fhome/vlia08/ImageCaptioning/inference.py", line 65, in <module>
    inference = Inference(args.images_path)
  File "/fhome/vlia08/ImageCaptioning/inference.py", line 19, in __init__
    self.model = AutoModelForVision2Seq.from_pretrained(
  File "/export/fhome/vlia08/MyVirtualEnv/lib/python3.8/site-packages/transformers/models/auto/auto_factory.py", line 564, in from_pretrained
    return model_class.from_pretrained(
  File "/export/fhome/vlia08/MyVirtualEnv/lib/python3.8/site-packages/transformers/modeling_utils.py", line 3657, in from_pretrained
    hf_quantizer.validate_environment(
  File "/export/fhome/vlia08/MyVirtualEnv/lib/python3.8/site-packages/transformers/quantizers/quantizer_bnb_8bit.py", line 77, in validate_environment
    from ..integrations import validate_bnb_backend_availability
  File "<frozen importlib._bootstrap>", line 1039, in _handle_fromlist
  File "/export/fhome/vlia08/MyVirtualEnv/lib/python3.8/site-packages/transformers/utils/import_utils.py", line 1766, in __getattr__
    module = self._get_module(self._class_to_module[name])
  File "/export/fhome/vlia08/MyVirtualEnv/lib/python3.8/site-packages/transformers/utils/import_utils.py", line 1780, in _get_module
    raise RuntimeError(
RuntimeError: Failed to import transformers.integrations.bitsandbytes because of the following error (look up to see its traceback):

        CUDA Setup failed despite GPU being available. Please run the following command to get more information:

        python -m bitsandbytes

        Inspect the output of the command and see if you can locate CUDA libraries. You might need to add them
        to your LD_LIBRARY_PATH. If you suspect a bug, please take the information from python -m bitsandbytes
        and open an issue at: https://github.com/TimDettmers/bitsandbytes/issues
